Workbook

Sheet Q2 16
B2: Q3 16 Allocation
B4: Income Profile
H5: Q1 | I5: Q2 | J5: Delta (Q3-Q2)
B6: Statutory Max | D6: Q3 2016 | E6: Vector | F6: Vector Weight | G6: Active USD Long
B7: Equities: | C7: 0.2 | D7: =F7+F8 -> 0.16 | E7: Cell D | F7: 0.1 | H7: 0.15 | I7: 0.13 | J7: =F7-I7 -> -0.03
E8: Exclusif 21 | F8: 0.06 | H8: 0.05 | I8: 0.05 | J8: =F8-I8 -> 0.01
B9: Bonds: | C9: 1 | D9: =F9+F10+F11 -> 0.52 | E9: Cell C | F9: 0.37 | H9: 0.4 | I9: 0.37 | J9: =F9-I9 -> 0
E10: KKR NB C L/S TBC | F10: 0.05 | H10: 0.08 | I10: 0.08 | J10: =F10-I10 -> -0.03
E11: TFC Bonds | F11: 0.1 | H11: 0.07 | I11: 0.1 | J11: =F11-I11 -> 0
B12: Alternatives: | C12: 0.15 | D12: =SUM(F12:F15) -> 0.17 | E12: Gold | F12: 0.07 | H12: 0 | I12: 0 | J12: =F12-I12 -> 0.07
E13: Tactical | F13: 0.07 | H13: 0.07 | I13: 0.07 | J13: =F13-I13 -> 0
E14: Abrax | F14: 0.03 | H14: 0.03 | I14: 0.03 | J14: =F14-I14 -> 0
E15: Syquant | F15: 0 | H15: 0 | I15: 0 | J15: =F15-I15 -> 0
B16: Cash: | C16: 1 | D16: =100%-D12-D9-D7 -> 0.15 | G16: 0.1 | H16: 0.15 | I16: 0.17 | J16: =D16-I16 -> -0.02
B19: Conservative Profile
H20: =H5 -> Q1 | I20: Q2 | J20: =J5 -> Delta (Q3-Q2)
B21: Statutory Max | D21: =D6 -> Q3 2016 | E21: Vector | F21: Vector Weight | G21: Active USD Long
B22: Equities: | C22: 0.3 | D22: =F22+F24+F23 -> 0.28 | E22: Cell D | F22: 0.2 | H22: 0.22 | I22: 0.2 | J22: =F22-I22 -> 0
E23: TFC Small Caps | F23: 0.03 | H23: 0.03 | I23: 0.03 | J23: =F23-I23 -> 0
E24: Exclusif 21 | F24: 0.05 | H24: 0.05 | I24: 0.05 | J24: =F24-I24 -> 0
B25: Bonds: | C25: 0.8 | D25: =F25+F26+F27 -> 0.4 | E25: Cell C | F25: 0.28 | H25: 0.3 | I25: 0.28 | J25: =F25-I25 -> 0
E26: KKR NB C L/S TBC | F26: 0.05 | H26: 0.07 | I26: 0.07 | J26: =F26-I26 -> -0.02
E27: TFC Bonds | F27: 0.07 | H27: 0.05 | I27: 0.07 | J27: =F27-I27 -> 0
B28: Alternatives: | C28: 0.25 | D28: =SUM(F28:F32) -> 0.23 | E28: Gold | F28: 0.05 | H28: 0 | I28: 0 | J28: =F28-I28 -> 0.05
E29: Tactical | F29: 0.09 | H29: 0.03 | I29: 0.07 | J29: =F29-I29 -> 0.02
E30: Abrax | F30: 0.05 | H30: 0.05 | I30: 0.05 | J30: =F30-I30 -> 0
E31: Syquant | F31: 0 | H31: 0 | I31: 0 | J31: =F31-I31 -> 0
E32: Cimco | F32: 0.04 | H32: 0.04 | I32: 0.04 | J32: =F32-I32 -> 0
B33: Cash: | C33: 1 | D33: =100%-D28-D25-D22 -> 0.09 | G33: 0.15 | H33: 0.16 | I33: 0.14 | J33: =D33-I33 -> -0.05
B37: Balanced Profile
H38: =H20 -> Q1 | I38: Q2 | J38: =J20 -> Delta (Q3-Q2)
B39: Statutory Max | D39: =D21 -> Q3 2016 | E39: Vector | F39: Vector Weight | G39: Active USD Long
B40: Equities: | C40: 0.7 | D40: =SUM(F40:F45) -> 0.6 | E40: Cell D | F40: 0.39 | H40: 0.42 | I40: 0.42 | J40: =F40-I40 -> -0.03
E41: Exclusif 21 | F41: 0.06 | H41: 0.06 | I41: 0.06 | J41: =F41-I41 -> 0
E42: TFC Small Caps | F42: 0.04 | H42: 0.03 | I42: 0.04 | J42: =F42-I42 -> 0
E43: Shanti India | F43: 0.04 | H43: 0.03 | I43: 0.04 | J43: =F43-I43 -> 0
E44: Liontrust UK small caps | F44: 0.03 | H44: 0 | I44: 0.03 | J44: =F44-I44 -> 0
E45: Liontrust Asian | F45: 0.04 | H45: 0.03 | I45: 0.04 | J45: =F45-I45 -> 0
B46: Bonds: | C46: 0.5 | D46: =F46+F47 -> 0.15 | E46: Cell C | F46: 0.15 | H46: 0.18 | I46: 0.15 | J46: =F46-I46 -> 0
E47: KKR NB C L/S TBC | F47: 0 | H47: 0.05 | I47: 0 | J47: =F47-I47 -> 0
...

Sheet Q3 16
R1: Estimated Downside Risk
M2: Return | R2: Average Correction
B3: Q3 16 Allocation | R3: Corr=1
L4: 12 Mos E® | N4: =SUM(N8:N19) -> 0.0296 | Q4: Risk= | S4: =SUM(S8:S19) -> 0.05965
B5: Income Profile
H6: Q2 | I6: Q3 | J6: Delta (Q3-Q2)
B7: Statutory Max | D7: Q3 2016 | E7: Vector | F7: Vector Weight | G7: Active USD Long
B8: Equities: | C8: 0.2 | D8: =F8+F9 -> 0.16 | E8: Cell D | F8: 0.11 | H8: ='Q2 16'!I7 -> 0.13 | I8: =F8 -> 0.11 | J8: =I8-H8 -> -0.02 | L8: 0.05 | N8: =L8*F8 -> 0.0055 | Q8: 0.15 | S8: =Q8*F8 -> 0.0165
E9: Exclusif 21 | F9: 0.05 | H9: ='Q2 16'!I8 -> 0.05 | I9: =F9 -> 0.05 | J9: =I9-H9 -> 0 | L9: 0.03 | N9: =L9*F9 -> 0.0015 | Q9: 0.1 | S9: =Q9*F9 -> 0.005
B10: Bonds: | C10: 1 | D10: =SUM(F10:F13) -> 0.51 | E10: Cell C | F10: 0.37 | H10: ='Q2 16'!I9 -> 0.37 | I10: =F10 -> 0.37 | J10: =I10-H10 -> 0 | L10: 0.03 | N10: =L10*F10 -> 0.0111 | Q10: 0.055 | S10: =Q10*F10 -> 0.02035
E11: KKR NB C L/S TBC | F11: 0 | H11: ='Q2 16'!I10 -> 0.08 | I11: =F11 -> 0 | J11: =I11-H11 -> -0.08 | N11: =L11*F11 -> 0 | S11: =Q11*F11 -> 0
E12: Arcano Fund | F12: 0.05 | H12: 0 | I12: =F12 -> 0.05 | J12: =I12-H12 -> 0.05 | L12: 0.04 | N12: =L12*F12 -> 0.002 | Q12: 0.02 | S12: =Q12*F12 -> 0.001
E13: TFC Bonds | F13: 0.09 | H13: ='Q2 16'!I11 -> 0.1 | I13: =F13 -> 0.09 | J13: =I13-H13 -> -0.01 | L13: 0.03 | N13: =L13*F13 -> 0.0027 | Q13: 0.1 | S13: =Q13*F13 -> 0.009
B14: Alternatives: | C14: 0.15 | D14: =SUM(F14:F17) -> 0.13 | E14: Gold | F14: 0 | H14: ='Q2 16'!I12 -> 0 | I14: =F14 -> 0 | J14: =I14-H14 -> 0 | N14: =L14*F14 -> 0 | S14: =Q14*F14 -> 0
E15: Tactical | F15: 0.07 | H15: ='Q2 16'!I13 -> 0.07 | I15: =F15 -> 0.07 | J15: =I15-H15 -> 0 | L15: 0.02 | N15: =L15*F15 -> 0.0014 | Q15: 0.02 | S15: =Q15*F15 -> 0.0014
E16: Abrax | F16: 0.03 | H16: ='Q2 16'!I14 -> 0.03 | I16: =F16 -> 0.03 | J16: =I16-H16 -> 0 | L16: 0.05 | N16: =L16*F16 -> 0.0015 | Q16: 0.04 | S16: =Q16*F16 -> 0.0012
E17: Commodities Fund | F17: 0.03 | H17: ='Q2 16'!I15 -> 0 | I17: =F17 -> 0.03 | J17: =I17-H17 -> 0.03 | L17: 0.05 | N17: =L17*F17 -> 0.0015 | Q17: 0.04 | S17: =Q17*F17 -> 0.0012
B18: Cash: | C18: 1 | D18: =100%-D14-D10-D8 -> 0.2 | G18: 0.08 | H18: ='Q2 16'!I16 -> 0.17 | I18: =D18 -> 0.2 | J18: =I18-H18 -> 0.03 | L18: -0.004 | N18: =I18*L18 -> -0.0008
K19: Active ccy | L19: 0.04 | N19: =L19*G18 -> 0.0032 | Q19: 0.05 | S19: =Q19*G18 -> 0.004
B22: Conservative Profile | L22: 12 Mos E® | N22: =SUM(N25:N38) -> 0.03138 | Q22: =Q4 -> Risk= | S22: =SUM(S25:S39) -> 0.0707
H23: =H6 -> Q2 | I23: =I6 -> Q3 | J23: =J6 -> Delta (Q3-Q2)
B24: Statutory Max | D24: =D7 -> Q3 2016 | E24: Vector | F24: Vector Weight | G24: Active USD Long
B25: Equities: | C25: 0.3 | D25: =F25+F27+F26 -> 0.23 | E25: Cell D | F25: 0.18 | H25: 0.22 | I25: =F25 -> 0.18 | J25: =I25-H25 -> -0.04 | L25: =L8 -> 0.05 | N25: =L25*F25 -> 0.009 | Q25: =Q8 -> 0.15 | S25: =Q25*F25 -> 0.027
E26: TFC Small Caps | F26: 0.02 | H26: 0.03 | I26: =F26 -> 0.02 | J26: =I26-H26 -> -0.01 | L26: 0.06 | N26: =L26*F26 -> 0.0012 | Q26: 0.2 | S26: =Q26*F26 -> 0.004
E27: Exclusif 21 | F27: 0.03 | H27: 0.05 | I27: =F27 -> 0.03 | J27: =I27-H27 -> -0.02 | L27: =L9 -> 0.03 | N27: =L27*F27 -> 0.0009 | Q27: =Q9 -> 0.1 | S27: =Q27*F27 -> 0.003
B28: Bonds: | C28: 0.8 | D28: =SUM(F28:F31) -> 0.41 | E28: Cell C | F28: 0.3 | H28: 0.3 | I28: =F28 -> 0.3 | J28: =I28-H28 -> 0 | L28: =L10 -> 0.03 | N28: =L28*F28 -> 0.009 | Q28: =Q10 -> 0.055 | S28: =Q28*F28 -> 0.0165
E29: KKR NB C L/S TBC | F29: 0 | H29: 0.07 | I29: =F29 -> 0 | J29: =I29-H29 -> -0.07 | N29: =L29*F29 -> 0 | S29: =Q29*F29 -> 0
E30: Arcano Fund | F30: 0.04 | H30: 0 | I30: =F30 -> 0.04 | J30: =I30-H30 -> 0.04 | L30: =L12 -> 0.04 | N30: =L30*F30 -> 0.0016 | Q30: =Q12 -> 0.02 | S30: =Q30*F30 -> 0.0008
E31: TFC Bonds | F31: 0.07 | H31: 0.05 | I31: =F31 -> 0.07 | J31: =I31-H31 -> 0.02 | L31: =L13 -> 0.03 | N31: =L31*F31 -> 0.0021 | Q31: =Q13 -> 0.1 | S31: =Q31*F31 -> 0.007
B32: Alternatives: | C32: 0.25 | D32: =SUM(F32:F36) -> 0.18 | E32: Gold | F32: 0 | H32: 0 | I32: =F32 -> 0 | J32: =I32-H32 -> 0 | N32: =L32*F32 -> 0 | S32: =Q32*F32 -> 0
E33: Tactical | F33: 0.09 | H33: 0.03 | I33: =F33 -> 0.09 | J33: =I33-H33 -> 0.06 | L33: =L15 -> 0.02 | N33: =L33*F33 -> 0.0018 | Q33: =Q15 -> 0.02 | S33: =Q33*F33 -> 0.0018
E34: Abrax | F34: 0.05 | H34: 0.05 | I34: =F34 -> 0.05 | J34: =I34-H34 -> 0 | L34: =L16 -> 0.05 | N34: =L34*F34 -> 0.0025 | Q34: =Q16 -> 0.04 | S34: =Q34*F34 -> 0.002
E35: Syquant | F35: 0 | H35: 0 | I35: =F35 -> 0 | J35: =I35-H35 -> 0 | N35: =L35*F35 -> 0 | S35: =Q35*F35 -> 0
E36: Cimco | F36: 0.04 | H36: 0.04 | I36: =F36 -> 0.04 | J36: =I36-H36 -> 0 | L36: 0.05 | N36: =L36*F36 -> 0.002 | Q36: 0.05 | S36: =Q36*F36 -> 0.002
E37: Commodities Fund | F37: 0.04 | H37: 0 | I37: =F37 -> 0.04 | J37: =I37-H37 -> 0.04 | L37: =L17 -> 0.05 | N37: =L37*F37 -> 0.002 | Q37: =Q17 -> 0.04 | S37: =Q37*F37 -> 0.0016
B38: Cash: | C38: 1 | D38: =100%-D32-D28-D25 -> 0.18 | G38: 0.1 | H38: 0.16 | I38: =D38 -> 0.18 | J38: =I38-H38 -> 0.02 | L38: =L18 -> -0.004 | N38: =L38*D38 -> -0.00072
Q39: =Q19 -> 0.05 | S39: =Q39*G38 -> 0.005
B42: Balanced Profile | L42: 12 Mos E® | N42: =SUM(N45:N59) -> 0.03958 | Q42: =Q22 -> Risk= | S42: =SUM(S45:S59) -> 0.0926
H43: =H23 -> Q2 | I43: =I23 -> Q3 | J43: =J23 -> Delta (Q3-Q2)
B44: Statutory Max | D44: =D24 -> Q3 2016 | E44: Vector | F44: Vector Weight | G44: Active USD Long
...

Sheet Q1 16
B3: Q1 16 Allocation
B6: Income Profile
B8: Statutory Max | F8: Allocations Q12016 | H8: Vector | I8: Vector Weight | K8: Active USD Long
C9: Equities: | D9: 0.2 | F9: =I9+I10 -> 0.2 | H9: Cell D | I9: 0.15
H10: Exclusif 21 | I10: 0.05
C11: Bonds: | F11: =I11+I12+I13 -> 0.55 | H11: Cell C | I11: 0.4
H12: KKR | I12: 0.08
H13: TFC Bonds | I13: 0.07
C14: Alternatives: | F14: =SUM(I14:I17) -> 0.1 | H14: Loan fund | I14: 0
H15: Tactical | I15: 0.07
H16: Abrax | I16: 0.03
H17: Syquant | I17: 0
C18: Cash: | F18: =100%-F14-F11-F9 -> 0.15
K19: 10 to 15%
B24: Conservative Profile
B26: Statutory Max | F26: Allocations Q12016 | H26: Vector | I26: Vector Weight | K26: Active USD Long
C27: Equities: | D27: 0.3 | F27: =I27+I29+I28 -> 0.3 | H27: Cell D | I27: 0.22
H28: TFC Small Caps | I28: 0.03
H29: Exclusif 21 | I29: 0.05
C30: Bonds: | F30: =I30+I31+I32 -> 0.42 | H30: Cell C | I30: 0.3
H31: KKR | I31: 0.07
H32: TFC Bonds | I32: 0.05
C33: Alternatives: | F33: =SUM(I33:I37) -> 0.12 | H33: Loan Fund | I33: 0
H34: Tactical | I34: 0.03
H35: Abrax | I35: 0.05
H36: Syquant | I36: 0
H37: Cimco | I37: 0.04
C38: Cash: | F38: =100%-F33-F30-F27 -> 0.16 | K38: 20 to 25%
B43: Balanced Profile
B45: Statutory Max | F45: Allocations Q12016 | H45: Vector | I45: Vector Weight | K45: Active USD Long
C46: Equities: | D46: 0.7 | F46: =I46+I47+I49+I50+I48 -> 0.57 | H46: Cell D | I46: 0.42
H47: Exclusif 21 | I47: 0.06
H48: TFC Small Caps | I48: 0.03
H49: Shanti India | I49: 0.03
H50: Liontrust Asian | I50: 0.03
C51: Bonds: | F51: =I51+I52 -> 0.23 | H51: Cell C | I51: 0.18
H52: KKR | I52: 0.05
C53: Alternatives: | F53: =SUM(I53:I56) -> 0.15 | H53: Abrax | I53: 0.06
H54: Tactical | I54: 0.04 | K54: 20 to 25%
H55: Syquant | I55: 0
...

Sheet Sheet3
